Workbook

Sheet README
A1: Ads KPI model: ads analytics for a delivery marketplace, built on public ad data
A2: Not Swiggy data. Sources: iPinYou RTB logs (season 3, Oct 2013), Criteo Attribution, Criteo Uplift v2.1.
A3: Money: iPinYou in CNY (2013). Criteo cost is a transformed unit; compare campaigns, don't read it as currency.
A4: Oct 21-28 iPinYou totals are lower bounds (iPinYou withheld a test set); ratios are fair.
A6: Sheets
A7: KPI_Summary: totals and ratios from the daily table (SUM), plus per-advertiser KPIs (XLOOKUP).
A8: Segments: pivot-style summary of 675 campaigns (COUNTIFS / SUMIFS).
A9: Campaign_Lookup: type a campaign id, get its numbers and segment (XLOOKUP).
A10: Floor_Model: pick an exchange, a minimum floor and a retention rate; revenue and break-even update.
A11: AB_Test: A/B readout recomputed with formulas (NORM.S.INV, NORM.S.DIST).
A12: Daily, Advertisers, Campaigns, FloorData: values exported from the SQL layer.
A14: Yellow cells are inputs. Everything else is a formula or exported data.
... A16: Built from outputs/numbers.json; iPinYou window 2013-10-19 to 2013-10-28.

Sheet KPI_Summary
A1: Ads P&L KPIs (iPinYou, all days)
A3: Bids | B3: =SUM(Daily!B2:B11)
A4: Bids won | B4: =SUM(Daily!C2:C11)
A5: Win rate | B5: =B4/B3 | C5: stand-in for fill rate (bidder's view)
A6: Impressions | B6: =SUM(Daily!E2:E11) | C6: includes impressions with no matching bid
A7: Spend / revenue (CNY) | B7: =SUM(Daily!F2:F11) | C7: advertiser spend = marketplace ad revenue
A8: CPM (CNY per 1,000 imps) | B8: =B7*1000/B6 | C8: ratio of totals, not average of daily CPMs
A9: Clicks | B9: =SUM(Daily!H2:H11)
A10: CTR | B10: =B9/B6
A11: CPC (CNY) | B11: =B7/B9
A12: Conversions | B12: =SUM(Daily!K2:K11) | C12: landing-page visits, 2 advertisers only
A13: Best day by spend | B13: =INDEX(Daily!A2:A11,MATCH(MAX(Daily!F2:F11),Daily!F2:F11,0)) | C13: INDEX/MATCH
A16: Per advertiser (XLOOKUP into Advertisers)
A17: Advertiser id | B17: Category | C17: Spend (CNY) | D17: Spend share | E17: CPM (CNY) | F17: CTR | G17: Win rate
A18: 2821 | B18: =_xlfn.XLOOKUP($A18,Advertisers!$A:$A,Advertisers!$B:$B,"not found") | C18: =_xlfn.XLOOKUP($A18,Advertisers!$A:$A,Advertisers!$G:$G,"not found") | D18: =C18/SUM($C$18:$C$21) | E18: =_xlfn.XLOOKUP($A18,Advertisers!$A:$A,Advertisers!$I:$I,"not found") | F18: =_xlfn.XLOOKUP($A18,Advertisers!$A:$A,Advertisers!$K:$K,"not found") | G18: =_xlfn.XLOOKUP($A18,Advertisers!$A:$A,Advertisers!$E:$E,"not found")
A19: 2259 | B19: =_xlfn.XLOOKUP($A19,Advertisers!$A:$A,Advertisers!$B:$B,"not found") | C19: =_xlfn.XLOOKUP($A19,Advertisers!$A:$A,Advertisers!$G:$G,"not found") | D19: =C19/SUM($C$18:$C$21) | E19: =_xlfn.XLOOKUP($A19,Advertisers!$A:$A,Advertisers!$I:$I,"not found") | F19: =_xlfn.XLOOKUP($A19,Advertisers!$A:$A,Advertisers!$K:$K,"not found") | G19: =_xlfn.XLOOKUP($A19,Advertisers!$A:$A,Advertisers!$E:$E,"not found")
A20: 2261 | B20: =_xlfn.XLOOKUP($A20,Advertisers!$A:$A,Advertisers!$B:$B,"not found") | C20: =_xlfn.XLOOKUP($A20,Advertisers!$A:$A,Advertisers!$G:$G,"not found") | D20: =C20/SUM($C$18:$C$21) | E20: =_xlfn.XLOOKUP($A20,Advertisers!$A:$A,Advertisers!$I:$I,"not found") | F20: =_xlfn.XLOOKUP($A20,Advertisers!$A:$A,Advertisers!$K:$K,"not found") | G20: =_xlfn.XLOOKUP($A20,Advertisers!$A:$A,Advertisers!$E:$E,"not found")
A21: 2997 | B21: =_xlfn.XLOOKUP($A21,Advertisers!$A:$A,Advertisers!$B:$B,"not found") | C21: =_xlfn.XLOOKUP($A21,Advertisers!$A:$A,Advertisers!$G:$G,"not found") | D21: =C21/SUM($C$18:$C$21) | E21: =_xlfn.XLOOKUP($A21,Advertisers!$A:$A,Advertisers!$I:$I,"not found") | F21: =_xlfn.XLOOKUP($A21,Advertisers!$A:$A,Advertisers!$K:$K,"not found") | G21: =_xlfn.XLOOKUP($A21,Advertisers!$A:$A,Advertisers!$E:$E,"not found")

Sheet Segments
A1: Advertiser segments: pivot-style summary of 675 Criteo campaigns
A2: Split at median spend and median CPA. Built with COUNTIFS/SUMIFS over the Campaigns sheet.
A4: Segment | B4: Campaigns | C4: Spend | D4: Spend share | E4: Conversions | F4: CTR | G4: CPA | H4: Spend retention (wk4/wk1) | I4: Campaigns whose spend halved | J4: Action
A5: PROTECT | B5: =COUNTIFS(Campaigns!$O$2:$O$676,A5) | C5: =SUMIFS(Campaigns!$F$2:$F$676,Campaigns!$O$2:$O$676,A5) | D5: =C5/$C$9 | E5: =SUMIFS(Campaigns!$E$2:$E$676,Campaigns!$O$2:$O$676,A5) | F5: =SUMIFS(Campaigns!$D$2:$D$676,Campaigns!$O$2:$O$676,A5)/SUMIFS(Campaigns!$C$2:$C$676,Campaigns!$O$2:$O$676,A5) | G5: =C5/E5 | H5: =SUMIFS(Campaigns!$N$2:$N$676,Campaigns!$O$2:$O$676,A5)/SUMIFS(Campaigns!$M$2:$M$676,Campaigns!$O$2:$O$676,A5) | I5: =COUNTIFS(Campaigns!$O$2:$O$676,A5,Campaigns!$L$2:$L$676,"<0.5") | J5: big and efficient: keep, upsell
A6: FIX | B6: =COUNTIFS(Campaigns!$O$2:$O$676,A6) | C6: =SUMIFS(Campaigns!$F$2:$F$676,Campaigns!$O$2:$O$676,A6) | D6: =C6/$C$9 | E6: =SUMIFS(Campaigns!$E$2:$E$676,Campaigns!$O$2:$O$676,A6) | F6: =SUMIFS(Campaigns!$D$2:$D$676,Campaigns!$O$2:$O$676,A6)/SUMIFS(Campaigns!$C$2:$C$676,Campaigns!$O$2:$O$676,A6) | G6: =C6/E6 | H6: =SUMIFS(Campaigns!$N$2:$N$676,Campaigns!$O$2:$O$676,A6)/SUMIFS(Campaigns!$M$2:$M$676,Campaigns!$O$2:$O$676,A6) | I6: =COUNTIFS(Campaigns!$O$2:$O$676,A6,Campaigns!$L$2:$L$676,"<0.5") | J6: big but expensive conversions: optimise before they cut spend
A7: GROW | B7: =COUNTIFS(Campaigns!$O$2:$O$676,A7) | C7: =SUMIFS(Campaigns!$F$2:$F$676,Campaigns!$O$2:$O$676,A7) | D7: =C7/$C$9 | E7: =SUMIFS(Campaigns!$E$2:$E$676,Campaigns!$O$2:$O$676,A7) | F7: =SUMIFS(Campaigns!$D$2:$D$676,Campaigns!$O$2:$O$676,A7)/SUMIFS(Campaigns!$C$2:$C$676,Campaigns!$O$2:$O$676,A7) | G7: =C7/E7 | H7: =SUMIFS(Campaigns!$N$2:$N$676,Campaigns!$O$2:$O$676,A7)/SUMIFS(Campaigns!$M$2:$M$676,Campaigns!$O$2:$O$676,A7) | I7: =COUNTIFS(Campaigns!$O$2:$O$676,A7,Campaigns!$L$2:$L$676,"<0.5") | J7: efficient but small: pitch more budget
A8: WATCH | B8: =COUNTIFS(Campaigns!$O$2:$O$676,A8) | C8: =SUMIFS(Campaigns!$F$2:$F$676,Campaigns!$O$2:$O$676,A8) | D8: =C8/$C$9 | E8: =SUMIFS(Campaigns!$E$2:$E$676,Campaigns!$O$2:$O$676,A8) | F8: =SUMIFS(Campaigns!$D$2:$D$676,Campaigns!$O$2:$O$676,A8)/SUMIFS(Campaigns!$C$2:$C$676,Campaigns!$O$2:$O$676,A8) | G8: =C8/E8 | H8: =SUMIFS(Campaigns!$N$2:$N$676,Campaigns!$O$2:$O$676,A8)/SUMIFS(Campaigns!$M$2:$M$676,Campaigns!$O$2:$O$676,A8) | I8: =COUNTIFS(Campaigns!$O$2:$O$676,A8,Campaigns!$L$2:$L$676,"<0.5") | J8: small and expensive: low priority
A9: Total | B9: =SUM(B5:B8) | C9: =SUM(C5:C8) | D9: =SUM(D5:D8) | E9: =SUM(E5:E8) | F9: =SUM(Campaigns!$D$2:$D$676)/SUM(Campaigns!$C$2:$C$676) | G9: =C9/E9 | H9: =SUM(Campaigns!$N$2:$N$676)/SUM(Campaigns!$M$2:$M$676) | I9: =SUM(I5:I8)
A11: FIX vs PROTECT: cost per conversion is | B11: =G6/G5 | C11: higher for FIX, while FIX holds this share of spend: | D11: =D6
A12: Top 20% of campaigns hold this share of spend: | B12: =SUMIFS(Campaigns!$F$2:$F$676,Campaigns!$B$2:$B$676,"<="&ROUND(0.2*B9,0))/C9

Sheet Campaign_Lookup
A1: Look up any campaign
A3: Campaign id (type one) | B3: 15398570
A5: Spend rank (1 = biggest) | B5: =_xlfn.XLOOKUP($B$3,Campaigns!$A$2:$A$676,Campaigns!$B$2:$B$676,"no such campaign")
A6: Spend | B6: =_xlfn.XLOOKUP($B$3,Campaigns!$A$2:$A$676,Campaigns!$F$2:$F$676,"no such campaign")
A7: Share of all spend | B7: =_xlfn.XLOOKUP($B$3,Campaigns!$A$2:$A$676,Campaigns!$G$2:$G$676,"no such campaign")
A8: Conversions | B8: =_xlfn.XLOOKUP($B$3,Campaigns!$A$2:$A$676,Campaigns!$E$2:$E$676,"no such campaign")
A9: CTR | B9: =_xlfn.XLOOKUP($B$3,Campaigns!$A$2:$A$676,Campaigns!$I$2:$I$676,"no such campaign")
A10: CVR (conversions / clicks) | B10: =_xlfn.XLOOKUP($B$3,Campaigns!$A$2:$A$676,Campaigns!$J$2:$J$676,"no such campaign")
A11: CPA (cost per conversion) | B11: =_xlfn.XLOOKUP($B$3,Campaigns!$A$2:$A$676,Campaigns!$K$2:$K$676,"no such campaign")
A12: Spend retention wk4 / wk1 | B12: =_xlfn.XLOOKUP($B$3,Campaigns!$A$2:$A$676,Campaigns!$L$2:$L$676,"no such campaign")
A13: Segment | B13: =_xlfn.XLOOKUP($B$3,Campaigns!$A$2:$A$676,Campaigns!$O$2:$O$676,"no such campaign")
A15: Median CPA of all campaigns | B15: =MEDIAN(Campaigns!$K$2:$K$676)
A16: This campaign's CPA vs median | B16: =IFERROR(B11/B15,"-")

Sheet Floor_Model
A1: Minimum floor price: what would it earn?
A2: New floor = max(current floor, X). Impressions that paid less than X are at risk: a share r still sells at X, the rest is lost (ADR 0007). r is unknown; an A/B test measures it.
A4: Exchange | B4: All
A5: Minimum floor X (fen per 1,000 imps) | B5: 30
A6: Retention r (share of at-risk imps that still sell) | B6: 0.5
A9: Revenue today (CNY) | B9: =SUMIFS(FloorData!$G$2:$G$97,FloorData!$A$2:$A$97,$B$4,FloorData!$B$2:$B$97,$B$5)
A10: Impressions at risk (paid < X) | B10: =SUMIFS(FloorData!$D$2:$D$97,FloorData!$A$2:$A$97,$B$4,FloorData!$B$2:$B$97,$B$5)
A11: Share of impressions at risk | B11: =B10/SUMIFS(FloorData!$C$2:$C$97,FloorData!$A$2:$A$97,$B$4,FloorData!$B$2:$B$97,$B$5)
A12: Revenue if every at-risk imp is lost (r = 0) | B12: =SUMIFS(FloorData!$H$2:$H$97,FloorData!$A$2:$A$97,$B$4,FloorData!$B$2:$B$97,$B$5) | C12: lower bound
A13: Revenue at your r | B13: =B12+$B$6*$B$5*SUMIFS(FloorData!$E$2:$E$97,FloorData!$A$2:$A$97,$B$4,FloorData!$B$2:$B$97,$B$5)/100000 | C13: safe revenue + r × X × sellable at-risk imps
A14: Change vs today | B14: =B13/B9-1
A15: Break-even r | B15: =IFERROR((B9-B12)/($B$5*SUMIFS(FloorData!$E$2:$E$97,FloorData!$A$2:$A$97,$B$4,FloorData!$B$2:$B$97,$B$5)/100000),"n/a") | C15: below this r, the floor loses money
A16: Verdict at your r | B16: =IF(B5=0,"no change",IF(B13>=B9,"raises revenue","loses revenue"))
A19: Sensitivity: revenue change vs today, by minimum floor (rows) and retention r (columns)
A20: X \ r | B20: 0 | C20: 0.25 | D20: 0.5 | E20: 0.75 | F20: 1
A21: 0 | B21: =(SUMIFS(FloorData!$H$2:$H$97,FloorData!$A$2:$A$97,$B$4,FloorData!$B$2:$B$97,$A21)+B$20*$A21*SUMIFS(FloorData!$E$2:$E$97,FloorData!$A$2:$A$97,$B$4,FloorData!$B$2:$B$97,$A21)/100000)/SUMIFS(FloorData!$G$2:$G$97,FloorData!$A$2:$A$97,$B$4,FloorData!$B$2:$B$97,$A21)-1 | C21: =(SUMIFS(FloorData!$H$2:$H$97,FloorData!$A$2:$A$97,$B$4,FloorData!$B$2:$B$97,$A21)+C$20*$A21*SUMIFS(FloorData!$E$2:$E$97,FloorData!$A$2:$A$97,$B$4,FloorData!$B$2:$B$97,$A21)/100000)/SUMIFS(FloorData!$G$2:$G$97,FloorData!$A$2:$A$97,$B$4,FloorData!$B$2:$B$97,$A21)-1 | D21: =(SUMIFS(FloorData!$H$2:$H$97,FloorData!$A$2:$A$97,$B$4,FloorData!$B$2:$B$97,$A21)+D$20*$A21*SUMIFS(FloorData!$E$2:$E$97,FloorData!$A$2:$A$97,$B$4,FloorData!$B$2:$B$97,$A21)/100000)/SUMIFS(FloorData!$G$2:$G$97,FloorData!$A$2:$A$97,$B$4,FloorData!$B$2:$B$97,$A21)-1 | E21: =(SUMIFS(FloorData!$H$2:$H$97,FloorData!$A$2:$A$97,$B$4,FloorData!$B$2:$B$97,$A21)+E$20*$A21*SUMIFS(FloorData!$E$2:$E$97,FloorData!$A$2:$A$97,$B$4,FloorData!$B$2:$B$97,$A21)/100000)/SUMIFS(FloorData!$G$2:$G$97,FloorData!$A$2:$A$97,$B$4,FloorData!$B$2:$B$97,$A21)-1 | F21: =(SUMIFS(FloorData!$H$2:$H$97,FloorData!$A$2:$A$97,$B$4,FloorData!$B$2:$B$97,$A21)+F$20*$A21*SUMIFS(FloorData!$E$2:$E$97,FloorData!$A$2:$A$97,$B$4,FloorData!$B$2:$B$97,$A21)/100000)/SUMIFS(FloorData!$G$2:$G$97,FloorData!$A$2:$A$97,$B$4,FloorData!$B$2:$B$97,$A21)-1
A22: 10 | B22: =(SUMIFS(FloorData!$H$2:$H$97,FloorData!$A$2:$A$97,$B$4,FloorData!$B$2:$B$97,$A22)+B$20*$A22*SUMIFS(FloorData!$E$2:$E$97,FloorData!$A$2:$A$97,$B$4,FloorData!$B$2:$B$97,$A22)/100000)/SUMIFS(FloorData!$G$2:$G$97,FloorData!$A$2:$A$97,$B$4,FloorData!$B$2:$B$97,$A22)-1 | C22: =(SUMIFS(FloorData!$H$2:$H$97,FloorData!$A$2:$A$97,$B$4,FloorData!$B$2:$B$97,$A22)+C$20*$A22*SUMIFS(FloorData!$E$2:$E$97,FloorData!$A$2:$A$97,$B$4,FloorData!$B$2:$B$97,$A22)/100000)/SUMIFS(FloorData!$G$2:$G$97,FloorData!$A$2:$A$97,$B$4,FloorData!$B$2:$B$97,$A22)-1 | D22: =(SUMIFS(FloorData!$H$2:$H$97,FloorData!$A$2:$A$97,$B$4,FloorData!$B$2:$B$97,$A22)+D$20*$A22*SUMIFS(FloorData!$E$2:$E$97,FloorData!$A$2:$A$97,$B$4,FloorData!$B$2:$B$97,$A22)/100000)/SUMIFS(FloorData!$G$2:$G$97,FloorData!$A$2:$A$97,$B$4,FloorData!$B$2:$B$97,$A22)-1 | E22: =(SUMIFS(FloorData!$H$2:$H$97,FloorData!$A$2:$A$97,$B$4,FloorData!$B$2:$B$97,$A22)+E$20*$A22*SUMIFS(FloorData!$E$2:$E$97,FloorData!$A$2:$A$97,$B$4,FloorData!$B$2:$B$97,$A22)/100000)/SUMIFS(FloorData!$G$2:$G$97,FloorData!$A$2:$A$97,$B$4,FloorData!$B$2:$B$97,$A22)-1 | F22: =(SUMIFS(FloorData!$H$2:$H$97,FloorData!$A$2:$A$97,$B$4,FloorData!$B$2:$B$97,$A22)+F$20*$A22*SUMIFS(FloorData!$E$2:$E$97,FloorData!$A$2:$A$97,$B$4,FloorData!$B$2:$B$97,$A22)/100000)/SUMIFS(FloorData!$G$2:$G$97,FloorData!$A$2:$A$97,$B$4,FloorData!$B$2:$B$97,$A22)-1
A23: 20 | B23: =(SUMIFS(FloorData!$H$2:$H$97,FloorData!$A$2:$A$97,$B$4,FloorData!$B$2:$B$97,$A23)+B$20*$A23*SUMIFS(FloorData!$E$2:$E$97,FloorData!$A$2:$A$97,$B$4,FloorData!$B$2:$B$97,$A23)/100000)/SUMIFS(FloorData!$G$2:$G$97,FloorData!$A$2:$A$97,$B$4,FloorData!$B$2:$B$97,$A23)-1 | C23: =(SUMIFS(FloorData!$H$2:$H$97,FloorData!$A$2:$A$97,$B$4,FloorData!$B$2:$B$97,$A23)+C$20*$A23*SUMIFS(FloorData!$E$2:$E$97,FloorData!$A$2:$A$97,$B$4,FloorData!$B$2:$B$97,$A23)/100000)/SUMIFS(FloorData!$G$2:$G$97,FloorData!$A$2:$A$97,$B$4,FloorData!$B$2:$B$97,$A23)-1 | D23: =(SUMIFS(FloorData!$H$2:$H$97,FloorData!$A$2:$A$97,$B$4,FloorData!$B$2:$B$97,$A23)+D$20*$A23*SUMIFS(FloorData!$E$2:$E$97,FloorData!$A$2:$A$97,$B$4,FloorData!$B$2:$B$97,$A23)/100000)/SUMIFS(FloorData!$G$2:$G$97,FloorData!$A$2:$A$97,$B$4,FloorData!$B$2:$B$97,$A23)-1 | E23: =(SUMIFS(FloorData!$H$2:$H$97,FloorData!$A$2:$A$97,$B$4,FloorData!$B$2:$B$97,$A23)+E$20*$A23*SUMIFS(FloorData!$E$2:$E$97,FloorData!$A$2:$A$97,$B$4,FloorData!$B$2:$B$97,$A23)/100000)/SUMIFS(FloorData!$G$2:$G$97,FloorData!$A$2:$A$97,$B$4,FloorData!$B$2:$B$97,$A23)-1 | F23: =(SUMIFS(FloorData!$H$2:$H$97,FloorData!$A$2:$A$97,$B$4,FloorData!$B$2:$B$97,$A23)+F$20*$A23*SUMIFS(FloorData!$E$2:$E$97,FloorData!$A$2:$A$97,$B$4,FloorData!$B$2:$B$97,$A23)/100000)/SUMIFS(FloorData!$G$2:$G$97,FloorData!$A$2:$A$97,$B$4,FloorData!$B$2:$B$97,$A23)-1
A24: 30 | B24: =(SUMIFS(FloorData!$H$2:$H$97,FloorData!$A$2:$A$97,$B$4,FloorData!$B$2:$B$97,$A24)+B$20*$A24*SUMIFS(FloorData!$E$2:$E$97,FloorData!$A$2:$A$97,$B$4,FloorData!$B$2:$B$97,$A24)/100000)/SUMIFS(FloorData!$G$2:$G$97,FloorData!$A$2:$A$97,$B$4,FloorData!$B$2:$B$97,$A24)-1 | C24: =(SUMIFS(FloorData!$H$2:$H$97,FloorData!$A$2:$A$97,$B$4,FloorData!$B$2:$B$97,$A24)+C$20*$A24*SUMIFS(FloorData!$E$2:$E$97,FloorData!$A$2:$A$97,$B$4,FloorData!$B$2:$B$97,$A24)/100000)/SUMIFS(FloorData!$G$2:$G$97,FloorData!$A$2:$A$97,$B$4,FloorData!$B$2:$B$97,$A24)-1 | D24: =(SUMIFS(FloorData!$H$2:$H$97,FloorData!$A$2:$A$97,$B$4,FloorData!$B$2:$B$97,$A24)+D$20*$A24*SUMIFS(FloorData!$E$2:$E$97,FloorData!$A$2:$A$97,$B$4,FloorData!$B$2:$B$97,$A24)/100000)/SUMIFS(FloorData!$G$2:$G$97,FloorData!$A$2:$A$97,$B$4,FloorData!$B$2:$B$97,$A24)-1 | E24: =(SUMIFS(FloorData!$H$2:$H$97,FloorData!$A$2:$A$97,$B$4,FloorData!$B$2:$B$97,$A24)+E$20*$A24*SUMIFS(FloorData!$E$2:$E$97,FloorData!$A$2:$A$97,$B$4,FloorData!$B$2:$B$97,$A24)/100000)/SUMIFS(FloorData!$G$2:$G$97,FloorData!$A$2:$A$97,$B$4,FloorData!$B$2:$B$97,$A24)-1 | F24: =(SUMIFS(FloorData!$H$2:$H$97,FloorData!$A$2:$A$97,$B$4,FloorData!$B$2:$B$97,$A24)+F$20*$A24*SUMIFS(FloorData!$E$2:$E$97,FloorData!$A$2:$A$97,$B$4,FloorData!$B$2:$B$97,$A24)/100000)/SUMIFS(FloorData!$G$2:$G$97,FloorData!$A$2:$A$97,$B$4,FloorData!$B$2:$B$97,$A24)-1
A25: 40 | B25: =(SUMIFS(FloorData!$H$2:$H$97,FloorData!$A$2:$A$97,$B$4,FloorData!$B$2:$B$97,$A25)+B$20*$A25*SUMIFS(FloorData!$E$2:$E$97,FloorData!$A$2:$A$97,$B$4,FloorData!$B$2:$B$97,$A25)/100000)/SUMIFS(FloorData!$G$2:$G$97,FloorData!$A$2:$A$97,$B$4,FloorData!$B$2:$B$97,$A25)-1 | C25: =(SUMIFS(FloorData!$H$2:$H$97,FloorData!$A$2:$A$97,$B$4,FloorData!$B$2:$B$97,$A25)+C$20*$A25*SUMIFS(FloorData!$E$2:$E$97,FloorData!$A$2:$A$97,$B$4,FloorData!$B$2:$B$97,$A25)/100000)/SUMIFS(FloorData!$G$2:$G$97,FloorData!$A$2:$A$97,$B$4,FloorData!$B$2:$B$97,$A25)-1 | D25: =(SUMIFS(FloorData!$H$2:$H$97,FloorData!$A$2:$A$97,$B$4,FloorData!$B$2:$B$97,$A25)+D$20*$A25*SUMIFS(FloorData!$E$2:$E$97,FloorData!$A$2:$A$97,$B$4,FloorData!$B$2:$B$97,$A25)/100000)/SUMIFS(FloorData!$G$2:$G$97,FloorData!$A$2:$A$97,$B$4,FloorData!$B$2:$B$97,$A25)-1 | E25: =(SUMIFS(FloorData!$H$2:$H$97,FloorData!$A$2:$A$97,$B$4,FloorData!$B$2:$B$97,$A25)+E$20*$A25*SUMIFS(FloorData!$E$2:$E$97,FloorData!$A$2:$A$97,$B$4,FloorData!$B$2:$B$97,$A25)/100000)/SUMIFS(FloorData!$G$2:$G$97,FloorData!$A$2:$A$97,$B$4,FloorData!$B$2:$B$97,$A25)-1 | F25: =(SUMIFS(FloorData!$H$2:$H$97,FloorData!$A$2:$A$97,$B$4,FloorData!$B$2:$B$97,$A25)+F$20*$A25*SUMIFS(FloorData!$E$2:$E$97,FloorData!$A$2:$A$97,$B$4,FloorData!$B$2:$B$97,$A25)/100000)/SUMIFS(FloorData!$G$2:$G$97,FloorData!$A$2:$A$97,$B$4,FloorData!$B$2:$B$97,$A25)-1
A26: 50 | B26: =(SUMIFS(FloorData!$H$2:$H$97,FloorData!$A$2:$A$97,$B$4,FloorData!$B$2:$B$97,$A26)+B$20*$A26*SUMIFS(FloorData!$E$2:$E$97,FloorData!$A$2:$A$97,$B$4,FloorData!$B$2:$B$97,$A26)/100000)/SUMIFS(FloorData!$G$2:$G$97,FloorData!$A$2:$A$97,$B$4,FloorData!$B$2:$B$97,$A26)-1 | C26: =(SUMIFS(FloorData!$H$2:$H$97,FloorData!$A$2:$A$97,$B$4,FloorData!$B$2:$B$97,$A26)+C$20*$A26*SUMIFS(FloorData!$E$2:$E$97,FloorData!$A$2:$A$97,$B$4,FloorData!$B$2:$B$97,$A26)/100000)/SUMIFS(FloorData!$G$2:$G$97,FloorData!$A$2:$A$97,$B$4,FloorData!$B$2:$B$97,$A26)-1 | D26: =(SUMIFS(FloorData!$H$2:$H$97,FloorData!$A$2:$A$97,$B$4,FloorData!$B$2:$B$97,$A26)+D$20*$A26*SUMIFS(FloorData!$E$2:$E$97,FloorData!$A$2:$A$97,$B$4,FloorData!$B$2:$B$97,$A26)/100000)/SUMIFS(FloorData!$G$2:$G$97,FloorData!$A$2:$A$97,$B$4,FloorData!$B$2:$B$97,$A26)-1 | E26: =(SUMIFS(FloorData!$H$2:$H$97,FloorData!$A$2:$A$97,$B$4,FloorData!$B$2:$B$97,$A26)+E$20*$A26*SUMIFS(FloorData!$E$2:$E$97,FloorData!$A$2:$A$97,$B$4,FloorData!$B$2:$B$97,$A26)/100000)/SUMIFS(FloorData!$G$2:$G$97,FloorData!$A$2:$A$97,$B$4,FloorData!$B$2:$B$97,$A26)-1 | F26: =(SUMIFS(FloorData!$H$2:$H$97,FloorData!$A$2:$A$97,$B$4,FloorData!$B$2:$B$97,$A26)+F$20*$A26*SUMIFS(FloorData!$E$2:$E$97,FloorData!$A$2:$A$97,$B$4,FloorData!$B$2:$B$97,$A26)/100000)/SUMIFS(FloorData!$G$2:$G$97,FloorData!$A$2:$A$97,$B$4,FloorData!$B$2:$B$97,$A26)-1
A27: 60 | B27: =(SUMIFS(FloorData!$H$2:$H$97,FloorData!$A$2:$A$97,$B$4,FloorData!$B$2:$B$97,$A27)+B$20*$A27*SUMIFS(FloorData!$E$2:$E$97,FloorData!$A$2:$A$97,$B$4,FloorData!$B$2:$B$97,$A27)/100000)/SUMIFS(FloorData!$G$2:$G$97,FloorData!$A$2:$A$97,$B$4,FloorData!$B$2:$B$97,$A27)-1 | C27: =(SUMIFS(FloorData!$H$2:$H$97,FloorData!$A$2:$A$97,$B$4,FloorData!$B$2:$B$97,$A27)+C$20*$A27*SUMIFS(FloorData!$E$2:$E$97,FloorData!$A$2:$A$97,$B$4,FloorData!$B$2:$B$97,$A27)/100000)/SUMIFS(FloorData!$G$2:$G$97,FloorData!$A$2:$A$97,$B$4,FloorData!$B$2:$B$97,$A27)-1 | D27: =(SUMIFS(FloorData!$H$2:$H$97,FloorData!$A$2:$A$97,$B$4,FloorData!$B$2:$B$97,$A27)+D$20*$A27*SUMIFS(FloorData!$E$2:$E$97,FloorData!$A$2:$A$97,$B$4,FloorData!$B$2:$B$97,$A27)/100000)/SUMIFS(FloorData!$G$2:$G$97,FloorData!$A$2:$A$97,$B$4,FloorData!$B$2:$B$97,$A27)-1 | E27: =(SUMIFS(FloorData!$H$2:$H$97,FloorData!$A$2:$A$97,$B$4,FloorData!$B$2:$B$97,$A27)+E$20*$A27*SUMIFS(FloorData!$E$2:$E$97,FloorData!$A$2:$A$97,$B$4,FloorData!$B$2:$B$97,$A27)/100000)/SUMIFS(FloorData!$G$2:$G$97,FloorData!$A$2:$A$97,$B$4,FloorData!$B$2:$B$97,$A27)-1 | F27: =(SUMIFS(FloorData!$H$2:$H$97,FloorData!$A$2:$A$97,$B$4,FloorData!$B$2:$B$97,$A27)+F$20*$A27*SUMIFS(FloorData!$E$2:$E$97,FloorData!$A$2:$A$97,$B$4,FloorData!$B$2:$B$97,$A27)/100000)/SUMIFS(FloorData!$G$2:$G$97,FloorData!$A$2:$A$97,$B$4,FloorData!$B$2:$B$97,$A27)-1
A28: 70 | B28: =(SUMIFS(FloorData!$H$2:$H$97,FloorData!$A$2:$A$97,$B$4,FloorData!$B$2:$B$97,$A28)+B$20*$A28*SUMIFS(FloorData!$E$2:$E$97,FloorData!$A$2:$A$97,$B$4,FloorData!$B$2:$B$97,$A28)/100000)/SUMIFS(FloorData!$G$2:$G$97,FloorData!$A$2:$A$97,$B$4,FloorData!$B$2:$B$97,$A28)-1 | C28: =(SUMIFS(FloorData!$H$2:$H$97,FloorData!$A$2:$A$97,$B$4,FloorData!$B$2:$B$97,$A28)+C$20*$A28*SUMIFS(FloorData!$E$2:$E$97,FloorData!$A$2:$A$97,$B$4,FloorData!$B$2:$B$97,$A28)/100000)/SUMIFS(FloorData!$G$2:$G$97,FloorData!$A$2:$A$97,$B$4,FloorData!$B$2:$B$97,$A28)-1 | D28: =(SUMIFS(FloorData!$H$2:$H$97,FloorData!$A$2:$A$97,$B$4,FloorData!$B$2:$B$97,$A28)+D$20*$A28*SUMIFS(FloorData!$E$2:$E$97,FloorData!$A$2:$A$97,$B$4,FloorData!$B$2:$B$97,$A28)/100000)/SUMIFS(FloorData!$G$2:$G$97,FloorData!$A$2:$A$97,$B$4,FloorData!$B$2:$B$97,$A28)-1 | E28: =(SUMIFS(FloorData!$H$2:$H$97,FloorData!$A$2:$A$97,$B$4,FloorData!$B$2:$B$97,$A28)+E$20*$A28*SUMIFS(FloorData!$E$2:$E$97,FloorData!$A$2:$A$97,$B$4,FloorData!$B$2:$B$97,$A28)/100000)/SUMIFS(FloorData!$G$2:$G$97,FloorData!$A$2:$A$97,$B$4,FloorData!$B$2:$B$97,$A28)-1 | F28: =(SUMIFS(FloorData!$H$2:$H$97,FloorData!$A$2:$A$97,$B$4,FloorData!$B$2:$B$97,$A28)+F$20*$A28*SUMIFS(FloorData!$E$2:$E$97,FloorData!$A$2:$A$97,$B$4,FloorData!$B$2:$B$97,$A28)/100000)/SUMIFS(FloorData!$G$2:$G$97,FloorData!$A$2:$A$97,$B$4,FloorData!$B$2:$B$97,$A28)-1
A29: 80 | B29: =(SUMIFS(FloorData!$H$2:$H$97,FloorData!$A$2:$A$97,$B$4,FloorData!$B$2:$B$97,$A29)+B$20*$A29*SUMIFS(FloorData!$E$2:$E$97,FloorData!$A$2:$A$97,$B$4,FloorData!$B$2:$B$97,$A29)/100000)/SUMIFS(FloorData!$G$2:$G$97,FloorData!$A$2:$A$97,$B$4,FloorData!$B$2:$B$97,$A29)-1 | C29: =(SUMIFS(FloorData!$H$2:$H$97,FloorData!$A$2:$A$97,$B$4,FloorData!$B$2:$B$97,$A29)+C$20*$A29*SUMIFS(FloorData!$E$2:$E$97,FloorData!$A$2:$A$97,$B$4,FloorData!$B$2:$B$97,$A29)/100000)/SUMIFS(FloorData!$G$2:$G$97,FloorData!$A$2:$A$97,$B$4,FloorData!$B$2:$B$97,$A29)-1 | D29: =(SUMIFS(FloorData!$H$2:$H$97,FloorData!$A$2:$A$97,$B$4,FloorData!$B$2:$B$97,$A29)+D$20*$A29*SUMIFS(FloorData!$E$2:$E$97,FloorData!$A$2:$A$97,$B$4,FloorData!$B$2:$B$97,$A29)/100000)/SUMIFS(FloorData!$G$2:$G$97,FloorData!$A$2:$A$97,$B$4,FloorData!$B$2:$B$97,$A29)-1 | E29: =(SUMIFS(FloorData!$H$2:$H$97,FloorData!$A$2:$A$97,$B$4,FloorData!$B$2:$B$97,$A29)+E$20*$A29*SUMIFS(FloorData!$E$2:$E$97,FloorData!$A$2:$A$97,$B$4,FloorData!$B$2:$B$97,$A29)/100000)/SUMIFS(FloorData!$G$2:$G$97,FloorData!$A$2:$A$97,$B$4,FloorData!$B$2:$B$97,$A29)-1 | F29: =(SUMIFS(FloorData!$H$2:$H$97,FloorData!$A$2:$A$97,$B$4,FloorData!$B$2:$B$97,$A29)+F$20*$A29*SUMIFS(FloorData!$E$2:$E$97,FloorData!$A$2:$A$97,$B$4,FloorData!$B$2:$B$97,$A29)/100000)/SUMIFS(FloorData!$G$2:$G$97,FloorData!$A$2:$A$97,$B$4,FloorData!$B$2:$B$97,$A29)-1
A30: 90 | B30: =(SUMIFS(FloorData!$H$2:$H$97,FloorData!$A$2:$A$97,$B$4,FloorData!$B$2:$B$97,$A30)+B$20*$A30*SUMIFS(FloorData!$E$2:$E$97,FloorData!$A$2:$A$97,$B$4,FloorData!$B$2:$B$97,$A30)/100000)/SUMIFS(FloorData!$G$2:$G$97,FloorData!$A$2:$A$97,$B$4,FloorData!$B$2:$B$97,$A30)-1 | C30: =(SUMIFS(FloorData!$H$2:$H$97,FloorData!$A$2:$A$97,$B$4,FloorData!$B$2:$B$97,$A30)+C$20*$A30*SUMIFS(FloorData!$E$2:$E$97,FloorData!$A$2:$A$97,$B$4,FloorData!$B$2:$B$97,$A30)/100000)/SUMIFS(FloorData!$G$2:$G$97,FloorData!$A$2:$A$97,$B$4,FloorData!$B$2:$B$97,$A30)-1 | D30: =(SUMIFS(FloorData!$H$2:$H$97,FloorData!$A$2:$A$97,$B$4,FloorData!$B$2:$B$97,$A30)+D$20*$A30*SUMIFS(FloorData!$E$2:$E$97,FloorData!$A$2:$A$97,$B$4,FloorData!$B$2:$B$97,$A30)/100000)/SUMIFS(FloorData!$G$2:$G$97,FloorData!$A$2:$A$97,$B$4,FloorData!$B$2:$B$97,$A30)-1 | E30: =(SUMIFS(FloorData!$H$2:$H$97,FloorData!$A$2:$A$97,$B$4,FloorData!$B$2:$B$97,$A30)+E$20*$A30*SUMIFS(FloorData!$E$2:$E$97,FloorData!$A$2:$A$97,$B$4,FloorData!$B$2:$B$97,$A30)/100000)/SUMIFS(FloorData!$G$2:$G$97,FloorData!$A$2:$A$97,$B$4,FloorData!$B$2:$B$97,$A30)-1 | F30: =(SUMIFS(FloorData!$H$2:$H$97,FloorData!$A$2:$A$97,$B$4,FloorData!$B$2:$B$97,$A30)+F$20*$A30*SUMIFS(FloorData!$E$2:$E$97,FloorData!$A$2:$A$97,$B$4,FloorData!$B$2:$B$97,$A30)/100000)/SUMIFS(FloorData!$G$2:$G$97,FloorData!$A$2:$A$97,$B$4,FloorData!$B$2:$B$97,$A30)-1
A31: 100 | B31: =(SUMIFS(FloorData!$H$2:$H$97,FloorData!$A$2:$A$97,$B$4,FloorData!$B$2:$B$97,$A31)+B$20*$A31*SUMIFS(FloorData!$E$2:$E$97,FloorData!$A$2:$A$97,$B$4,FloorData!$B$2:$B$97,$A31)/100000)/SUMIFS(FloorData!$G$2:$G$97,FloorData!$A$2:$A$97,$B$4,FloorData!$B$2:$B$97,$A31)-1 | C31: =(SUMIFS(FloorData!$H$2:$H$97,FloorData!$A$2:$A$97,$B$4,FloorData!$B$2:$B$97,$A31)+C$20*$A31*SUMIFS(FloorData!$E$2:$E$97,FloorData!$A$2:$A$97,$B$4,FloorData!$B$2:$B$97,$A31)/100000)/SUMIFS(FloorData!$G$2:$G$97,FloorData!$A$2:$A$97,$B$4,FloorData!$B$2:$B$97,$A31)-1 | D31: =(SUMIFS(FloorData!$H$2:$H$97,FloorData!$A$2:$A$97,$B$4,FloorData!$B$2:$B$97,$A31)+D$20*$A31*SUMIFS(FloorData!$E$2:$E$97,FloorData!$A$2:$A$97,$B$4,FloorData!$B$2:$B$97,$A31)/100000)/SUMIFS(FloorData!$G$2:$G$97,FloorData!$A$2:$A$97,$B$4,FloorData!$B$2:$B$97,$A31)-1 | E31: =(SUMIFS(FloorData!$H$2:$H$97,FloorData!$A$2:$A$97,$B$4,FloorData!$B$2:$B$97,$A31)+E$20*$A31*SUMIFS(FloorData!$E$2:$E$97,FloorData!$A$2:$A$97,$B$4,FloorData!$B$2:$B$97,$A31)/100000)/SUMIFS(FloorData!$G$2:$G$97,FloorData!$A$2:$A$97,$B$4,FloorData!$B$2:$B$97,$A31)-1 | F31: =(SUMIFS(FloorData!$H$2:$H$97,FloorData!$A$2:$A$97,$B$4,FloorData!$B$2:$B$97,$A31)+F$20*$A31*SUMIFS(FloorData!$E$2:$E$97,FloorData!$A$2:$A$97,$B$4,FloorData!$B$2:$B$97,$A31)/100000)/SUMIFS(FloorData!$G$2:$G$97,FloorData!$A$2:$A$97,$B$4,FloorData!$B$2:$B$97,$A31)-1
A32: 110 | B32: =(SUMIFS(FloorData!$H$2:$H$97,FloorData!$A$2:$A$97,$B$4,FloorData!$B$2:$B$97,$A32)+B$20*$A32*SUMIFS(FloorData!$E$2:$E$97,FloorData!$A$2:$A$97,$B$4,FloorData!$B$2:$B$97,$A32)/100000)/SUMIFS(FloorData!$G$2:$G$97,FloorData!$A$2:$A$97,$B$4,FloorData!$B$2:$B$97,$A32)-1 | C32: =(SUMIFS(FloorData!$H$2:$H$97,FloorData!$A$2:$A$97,$B$4,FloorData!$B$2:$B$97,$A32)+C$20*$A32*SUMIFS(FloorData!$E$2:$E$97,FloorData!$A$2:$A$97,$B$4,FloorData!$B$2:$B$97,$A32)/100000)/SUMIFS(FloorData!$G$2:$G$97,FloorData!$A$2:$A$97,$B$4,FloorData!$B$2:$B$97,$A32)-1 | D32: =(SUMIFS(FloorData!$H$2:$H$97,FloorData!$A$2:$A$97,$B$4,FloorData!$B$2:$B$97,$A32)+D$20*$A32*SUMIFS(FloorData!$E$2:$E$97,FloorData!$A$2:$A$97,$B$4,FloorData!$B$2:$B$97,$A32)/100000)/SUMIFS(FloorData!$G$2:$G$97,FloorData!$A$2:$A$97,$B$4,FloorData!$B$2:$B$97,$A32)-1 | E32: =(SUMIFS(FloorData!$H$2:$H$97,FloorData!$A$2:$A$97,$B$4,FloorData!$B$2:$B$97,$A32)+E$20*$A32*SUMIFS(FloorData!$E$2:$E$97,FloorData!$A$2:$A$97,$B$4,FloorData!$B$2:$B$97,$A32)/100000)/SUMIFS(FloorData!$G$2:$G$97,FloorData!$A$2:$A$97,$B$4,FloorData!$B$2:$B$97,$A32)-1 | F32: =(SUMIFS(FloorData!$H$2:$H$97,FloorData!$A$2:$A$97,$B$4,FloorData!$B$2:$B$97,$A32)+F$20*$A32*SUMIFS(FloorData!$E$2:$E$97,FloorData!$A$2:$A$97,$B$4,FloorData!$B$2:$B$97,$A32)/100000)/SUMIFS(FloorData!$G$2:$G$97,FloorData!$A$2:$A$97,$B$4,FloorData!$B$2:$B$97,$A32)-1
... A36: 150 | B36: =(SUMIFS(FloorData!$H$2:$H$97,FloorData!$A$2:$A$97,$B$4,FloorData!$B$2:$B$97,$A36)+B$20*$A36*SUMIFS(FloorData!$E$2:$E$97,FloorData!$A$2:$A$97,$B$4,FloorData!$B$2:$B$97,$A36)/100000)/SUMIFS(FloorData!$G$2:$G$97,FloorData!$A$2:$A$97,$B$4,FloorData!$B$2:$B$97,$A36)-1 | C36: =(SUMIFS(FloorData!$H$2:$H$97,FloorData!$A$2:$A$97,$B$4,FloorData!$B$2:$B$97,$A36)+C$20*$A36*SUMIFS(FloorData!$E$2:$E$97,FloorData!$A$2:$A$97,$B$4,FloorData!$B$2:$B$97,$A36)/100000)/SUMIFS(FloorData!$G$2:$G$97,FloorData!$A$2:$A$97,$B$4,FloorData!$B$2:$B$97,$A36)-1 | D36: =(SUMIFS(FloorData!$H$2:$H$97,FloorData!$A$2:$A$97,$B$4,FloorData!$B$2:$B$97,$A36)+D$20*$A36*SUMIFS(FloorData!$E$2:$E$97,FloorData!$A$2:$A$97,$B$4,FloorData!$B$2:$B$97,$A36)/100000)/SUMIFS(FloorData!$G$2:$G$97,FloorData!$A$2:$A$97,$B$4,FloorData!$B$2:$B$97,$A36)-1 | E36: =(SUMIFS(FloorData!$H$2:$H$97,FloorData!$A$2:$A$97,$B$4,FloorData!$B$2:$B$97,$A36)+E$20*$A36*SUMIFS(FloorData!$E$2:$E$97,FloorData!$A$2:$A$97,$B$4,FloorData!$B$2:$B$97,$A36)/100000)/SUMIFS(FloorData!$G$2:$G$97,FloorData!$A$2:$A$97,$B$4,FloorData!$B$2:$B$97,$A36)-1 | F36: =(SUMIFS(FloorData!$H$2:$H$97,FloorData!$A$2:$A$97,$B$4,FloorData!$B$2:$B$97,$A36)+F$20*$A36*SUMIFS(FloorData!$E$2:$E$97,FloorData!$A$2:$A$97,$B$4,FloorData!$B$2:$B$97,$A36)/100000)/SUMIFS(FloorData!$G$2:$G$97,FloorData!$A$2:$A$97,$B$4,FloorData!$B$2:$B$97,$A36)-1

Sheet AB_Test
A1: A/B readout: does showing ads raise conversion? (Criteo Uplift, 13.98M users)
A2: Counts are inputs; every statistic below is a formula. Design fixed before the readout (docs/EXPERIMENT.md).
B4: Treatment | C4: Control
A5: Users | B5: 11882655 | C5: 2096937
A6: Visits | B6: 576824 | C6: 80105
A7: Conversions | B7: 36711 | C7: 4063
A8: Exposed to an ad | B8: 428212 | C8: 0
A10: Alpha (two-sided) | B10: 0.05
A11: Intended treatment share | B11: 0.85
A13: Observed treatment share | B13: =B5/(B5+C5) | C13: SRM check: should match the intended share
A14: SRM chi-square | B14: =(B5-(B5+C5)*B11)^2/((B5+C5)*B11)+(C5-(B5+C5)*(1-B11))^2/((B5+C5)*(1-B11)) | C14: compare with 10.83 (p = 0.001, 1 df)
A15: Conversion rate, treatment | B15: =B7/B5
A16: Conversion rate, control | B16: =C7/C5
A17: Absolute lift (percentage points) | B17: =B15-B16
A18: Relative lift | B18: =B15/B16-1
A19: z critical | B19: =_xlfn.NORM.S.INV(1-B10/2) | C19: 1.96 for 95%
A20: Standard error (unpooled) | B20: =SQRT(B15*(1-B15)/B5+B16*(1-B16)/C5)
A21: 95% CI low | B21: =B17-B19*B20
A22: 95% CI high | B22: =B17+B19*B20
A23: Pooled rate | B23: =(B7+C7)/(B5+C5) | C23: used only for the test, assuming no difference
A24: z statistic | B24: =B17/SQRT(B23*(1-B23)*(1/B5+1/C5))
A25: p-value | B25: =2*(1-_xlfn.NORM.S.DIST(ABS(B24),TRUE)) | C25: shows 0 when smaller than spreadsheet precision
A26: Visit rate, treatment | B26: =B6/B5
A27: Visit rate, control | B27: =C6/C5
A28: Visit lift CI low (guardrail) | B28: =(B26-B27)-B19*SQRT(B26*(1-B26)/B5+B27*(1-B27)/C5) | C28: must be >= 0
A29: MDE, conversion (80% power) | B29: =(B19+_xlfn.NORM.S.INV(0.8))*SQRT(B16*(1-B16)*(1/B5+1/C5)) | C29: smallest lift this test could reliably detect
A30: Exposure rate in treatment | B30: =B8/B5
A31: Lift for users who saw an ad (CACE) | B31: =B17/B30 | C31: ITT / exposure rate
A32: Decision (pre-registered rule) | B32: =IF(B14>=10.83,"untrustworthy (SRM)",IF(AND(B21>0,B28>=0),"SHIP",IF(OR(B22<0,B33<0),"DON'T SHIP","INCONCLUSIVE"))) | C32: rule in docs/EXPERIMENT.md section 7
A33: Visit lift CI high (guardrail) | B33: =(B26-B27)+B19*SQRT(B26*(1-B26)/B5+B27*(1-B27)/C5)

Sheet Daily
A1: day | B1: bids | C1: bids_won | D1: win_rate | E1: impressions | F1: spend_cny | G1: cpm_cny | H1: clicks | I1: ctr | J1: cpc_cny | K1: conversions | L1: active_advertisers
A2: 2013-10-19 | B2: 352766 | C2: 227827 | D2: 0.6458 | E2: 227827 | F2: 197.65 | G2: 0.8675 | H2: 83 | I2: 0.000364 | J2: 2.3813 | K2: 16 | L2: 1
A3: 2013-10-20 | B3: 326830 | C3: 214022 | D3: 0.6548 | E3: 214022 | F3: 188.19 | G3: 0.8793 | H3: 65 | I3: 0.000304 | J3: 2.8952 | K3: 22 | L3: 1
A4: 2013-10-21 | B4: 1547653 | C4: 844982 | D4: 0.546 | E4: 844982 | F4: 762.19 | G4: 0.902 | H4: 509 | I4: 0.000602 | J4: 1.4974 | K4: 270 | L4: 2
A5: 2013-10-22 | B5: 1212083 | C5: 708834 | D5: 0.5848 | E5: 723510 | F5: 665.03 | G5: 0.9192 | H5: 401 | I5: 0.000554 | J5: 1.6584 | K5: 190 | L5: 2
A6: 2013-10-23 | B6: 1578272 | C6: 485170 | D6: 0.3074 | E6: 485170 | F6: 468.17 | G6: 0.965 | H6: 705 | I6: 0.001453 | J6: 0.6641 | K6: 89 | L6: 3
A7: 2013-10-24 | B7: 2184015 | C7: 642510 | D7: 0.2942 | E7: 645279 | F7: 586.76 | G7: 0.9093 | H7: 575 | I7: 0.000891 | J7: 1.0205 | K7: 104 | L7: 4
A8: 2013-10-25 | B8: 2230333 | C8: 703687 | D8: 0.3155 | E8: 706046 | F8: 676.97 | G8: 0.9588 | H8: 601 | I8: 0.000851 | J8: 1.1264 | K8: 86 | L8: 4
A9: 2013-10-26 | B9: 536934 | C9: 313027 | D9: 0.583 | E9: 313152 | F9: 268.6 | G9: 0.8577 | H9: 381 | I9: 0.001217 | J9: 0.705 | K9: 0 | L9: 3
A10: 2013-10-27 | B10: 597857 | C10: 273571 | D10: 0.4576 | E10: 273571 | F10: 197.34 | G10: 0.7213 | H10: 457 | I10: 0.00167 | J10: 0.4318 | K10: 0 | L10: 2
A11: 2013-10-28 | B11: 890676 | C11: 291075 | D11: 0.3268 | E11: 291075 | F11: 242.92 | G11: 0.8346 | H11: 81 | I11: 0.000278 | J11: 2.999 | K11: 0 | L11: 1

Sheet Advertisers
A1: advertiser_id | B1: category | C1: active_days | D1: bids | E1: win_rate | F1: impressions | G1: spend_cny | H1: spend_share | I1: cpm_cny | J1: clicks | K1: ctr | L1: cpc_cny | M1: conversions | N1: cvr | O1: cpa_cny
A2: 2821 | B2: Footwear | C2: 6 | D2: 5292053 | E2: 0.371 | F2: 1975823 | G2: 1857.09 | H2: 0.4366 | I2: 0.9399 | J2: 1226 | K2: 0.000621 | L2: 1.5148 | M2: 656 | N2: 0.5351 | O2: 2.8309
A3: 2259 | B3: Milk powder | C3: 7 | D3: 2987731 | E3: 0.4169 | F3: 1251506 | G3: 1211.56 | H3: 0.2848 | I3: 0.9681 | J3: 411 | K3: 0.000328 | L3: 2.9478 | M3: 121 | N3: 0.2944 | O3: 10.0129
A4: 2261 | B4: Telecom | C4: 5 | D4: 2159708 | E4: 0.4762 | F4: 1029884 | G4: 902.75 | H4: 0.2122 | I4: 0.8766 | J4: 304 | K4: 0.000295 | L4: 2.9696 | M4: 0
A5: 2997 | B5: Mobile app install | C5: 5 | D5: 1017927 | E5: 0.4591 | F5: 467421 | G5: 282.42 | H5: 0.0664 | I5: 0.6042 | J5: 1917 | K5: 0.004101 | L5: 0.1473 | M5: 0

Sheet Campaigns
A1: campaign | B1: spend_rank | C1: impressions | D1: clicks | E1: conversions | F1: spend | G1: spend_share | H1: cumulative_spend_share | I1: ctr | J1: cvr | K1: cpa | L1: spend_retention_w4_vs_w1 | M1: spend_w1 | N1: spend_w4 | O1: segment
A2: 15398570 | B2: 1 | C2: 378464 | D2: 135066 | E2: 10176 | F2: 155.5724 | G2: 0.032214 | H2: 0.0322 | I2: 0.356879 | J2: 0.0753 | K2: 0.015288 | L2: 1.7925 | M2: 28.1789 | N2: 50.512 | O2: PROTECT
A3: 15184511 | B3: 2 | C3: 256102 | D3: 93175 | E3: 18936 | F3: 153.8266 | G3: 0.031852 | H3: 0.0641 | I3: 0.36382 | J3: 0.2032 | K3: 0.008123 | L3: 1.1657 | M3: 31.402 | N3: 36.6068 | O3: PROTECT
A4: 5061834 | B4: 3 | C4: 299755 | D4: 85763 | E4: 2096 | F4: 141.2444 | G4: 0.029247 | H4: 0.0933 | I4: 0.28611 | J4: 0.0244 | K4: 0.067388 | L4: 0.7394 | M4: 39.1161 | N4: 28.923 | O4: FIX
A5: 10341182 | B5: 4 | C5: 437385 | D5: 194847 | E5: 25702 | F5: 139.1625 | G5: 0.028816 | H5: 0.1221 | I5: 0.445482 | J5: 0.1319 | K5: 0.005414 | L5: 0.947 | M5: 31.0491 | N5: 29.4035 | O5: PROTECT
A6: 32368244 | B6: 5 | C6: 161056 | D6: 77584 | E6: 21946 | F6: 138.0964 | G6: 0.028595 | H6: 0.1507 | I6: 0.481721 | J6: 0.2829 | K6: 0.006293 | L6: 0.7241 | M6: 37.9513 | N6: 27.48 | O6: PROTECT
A7: 29427842 | B7: 6 | C7: 239272 | D7: 79009 | E7: 7070 | F7: 131.0925 | G7: 0.027145 | H7: 0.1779 | I7: 0.330206 | J7: 0.0895 | K7: 0.018542 | L7: 1.1765 | M7: 23.5932 | N7: 27.7576 | O7: FIX
A8: 30491418 | B8: 7 | C8: 186644 | D8: 72873 | E8: 3842 | F8: 119.0515 | G8: 0.024652 | H8: 0.2025 | I8: 0.390438 | J8: 0.0527 | K8: 0.030987 | L8: 0.5932 | M8: 39.0217 | N8: 23.1461 | O8: FIX
A9: 28351001 | B9: 8 | C9: 222470 | D9: 138590 | E9: 6620 | F9: 103.7009 | G9: 0.021473 | H9: 0.224 | I9: 0.62296 | J9: 0.0478 | K9: 0.015665 | L9: 1.1033 | M9: 22.5628 | N9: 24.8946 | O9: PROTECT
A10: 18975823 | B10: 9 | C10: 217646 | D10: 100798 | E10: 7669 | F10: 82.1553 | G10: 0.017012 | H10: 0.241 | I10: 0.463128 | J10: 0.0761 | K10: 0.010713 | L10: 1.6875 | M10: 13.3475 | N10: 22.5238 | O10: PROTECT
A11: 17686799 | B11: 10 | C11: 381084 | D11: 112964 | E11: 5090 | F11: 79.4298 | G11: 0.016447 | H11: 0.2575 | I11: 0.296428 | J11: 0.0451 | K11: 0.015605 | L11: 1.1697 | M11: 16.9347 | N11: 19.8079 | O11: PROTECT
A12: 14661605 | B12: 11 | C12: 125045 | D12: 41244 | E12: 4262 | F12: 78.5231 | G12: 0.01626 | H12: 0.2737 | I12: 0.329833 | J12: 0.1033 | K12: 0.018424 | L12: 0.9611 | M12: 14.4363 | N12: 13.8747 | O12: FIX
A13: 6686701 | B13: 12 | C13: 194059 | D13: 76239 | E13: 4336 | F13: 68.8747 | G13: 0.014262 | H13: 0.288 | I13: 0.392865 | J13: 0.0569 | K13: 0.015884 | L13: 5.3204 | M13: 6.9378 | N13: 36.9119 | O13: PROTECT
... A200: 16307476 | B200: 199 | C200: 10721 | D200: 3551 | E200: 153 | F200: 5.1918 | G200: 0.001075 | H200: 0.8164 | I200: 0.331219 | J200: 0.0431 | K200: 0.033933 | L200: 0.7729 | M200: 1.3521 | N200: 1.045 | O200: FIX
A201: 26321366 | B201: 200 | C201: 42947 | D201: 12254 | E201: 488 | F201: 5.1665 | G201: 0.00107 | H201: 0.8175 | I201: 0.285328 | J201: 0.0398 | K201: 0.010587 | M201: 1.8872 | O201: PROTECT
A202: 5121534 | B202: 201 | C202: 12508 | D202: 3311 | E202: 136 | F202: 5.1402 | G202: 0.001064 | H202: 0.8185 | I202: 0.264711 | J202: 0.0411 | K202: 0.037796 | L202: 1.659 | M202: 0.7666 | N202: 1.2718 | O202: FIX
A203: 29614010 | B203: 202 | C203: 12237 | D203: 5046 | E203: 135 | F203: 5.1122 | G203: 0.001059 | H203: 0.8196 | I203: 0.412356 | J203: 0.0268 | K203: 0.037868 | L203: 2.1209 | M203: 0.7208 | N203: 1.5287 | O203: FIX
A204: 9810200 | B204: 203 | C204: 29866 | D204: 18502 | E204: 940 | F204: 5.1013 | G204: 0.001056 | H204: 0.8206 | I204: 0.6195 | J204: 0.0508 | K204: 0.005427 | L204: 1.3011 | M204: 1.0424 | N204: 1.3563 | O204: PROTECT
A205: 26091099 | B205: 204 | C205: 12603 | D205: 4266 | E205: 128 | F205: 5.0695 | G205: 0.00105 | H205: 0.8217 | I205: 0.338491 | J205: 0.03 | K205: 0.039606 | L205: 1.463 | M205: 0.8297 | N205: 1.2139 | O205: FIX
A206: 29862638 | B206: 205 | C206: 6915 | D206: 3054 | E206: 204 | F206: 5.0568 | G206: 0.001047 | H206: 0.8227 | I206: 0.441649 | J206: 0.0668 | K206: 0.024788 | L206: 0.9287 | M206: 1.2969 | N206: 1.2044 | O206: FIX
A207: 14104562 | B207: 206 | C207: 8226 | D207: 2817 | E207: 50 | F207: 5.0547 | G207: 0.001047 | H207: 0.8238 | I207: 0.342451 | J207: 0.0177 | K207: 0.101093 | L207: 0.6102 | M207: 1.6198 | N207: 0.9884 | O207: FIX
A208: 13462155 | B208: 207 | C208: 11683 | D208: 3788 | E208: 271 | F208: 5.0536 | G208: 0.001046 | H208: 0.8248 | I208: 0.324232 | J208: 0.0715 | K208: 0.018648 | L208: 1.0302 | M208: 1.2242 | N208: 1.2611 | O208: FIX
A209: 8710016 | B209: 208 | C209: 29496 | D209: 11601 | E209: 655 | F209: 5.0453 | G209: 0.001045 | H209: 0.8259 | I209: 0.393308 | J209: 0.0565 | K209: 0.007703 | L209: 0.6986 | M209: 1.2954 | N209: 0.9049 | O209: PROTECT
A210: 12987593 | B210: 209 | C210: 13196 | D210: 5185 | E210: 93 | F210: 4.9782 | G210: 0.001031 | H210: 0.8269 | I210: 0.392922 | J210: 0.0179 | K210: 0.053529 | L210: 2.7235 | M210: 0.6036 | N210: 1.6439 | O210: FIX
A211: 12089529 | B211: 210 | C211: 29711 | D211: 10639 | E211: 510 | F211: 4.92 | G211: 0.001019 | H211: 0.8279 | I211: 0.358083 | J211: 0.0479 | K211: 0.009647 | M211: 2.2534 | O211: PROTECT
A212: 14104561 | B212: 211 | C212: 10170 | D212: 2893 | E212: 51 | F212: 4.9172 | G212: 0.001018 | H212: 0.8289 | I212: 0.284464 | J212: 0.0176 | K212: 0.096416 | L212: 0.91 | M212: 1.1151 | N212: 1.0147 | O212: FIX
A213: 15743382 | B213: 212 | C213: 8619 | D213: 2377 | E213: 1639 | F213: 4.9043 | G213: 0.001016 | H213: 0.83 | I213: 0.275786 | J213: 0.6895 | K213: 0.002992 | L213: 1.6343 | M213: 1.054 | N213: 1.7226 | O213: PROTECT
A214: 9097340 | B214: 213 | C214: 5734 | D214: 2291 | E214: 182 | F214: 4.8282 | G214: 0.001 | H214: 0.831 | I214: 0.399547 | J214: 0.0794 | K214: 0.026529 | L214: 0.593 | M214: 1.2635 | N214: 0.7492 | O214: FIX
A215: 19661713 | B215: 214 | C215: 14715 | D215: 3064 | E215: 138 | F215: 4.8032 | G215: 0.000995 | H215: 0.8319 | I215: 0.208223 | J215: 0.045 | K215: 0.034806 | L215: 2.1443 | M215: 0.7523 | N215: 1.6132 | O215: FIX
A216: 5743167 | B216: 215 | C216: 7695 | D216: 2887 | E216: 199 | F216: 4.7503 | G216: 0.000984 | H216: 0.8329 | I216: 0.375179 | J216: 0.0689 | K216: 0.023871 | L216: 0.6937 | M216: 1.3184 | N216: 0.9145 | O216: FIX
A217: 15959620 | B217: 216 | C217: 9048 | D217: 3673 | E217: 67 | F217: 4.7193 | G217: 0.000977 | H217: 0.8339 | I217: 0.405946 | J217: 0.0182 | K217: 0.070437 | N217: 1.8796 | O217: FIX
A218: 15073876 | B218: 217 | C218: 91735 | D218: 28077 | E218: 186 | F218: 4.6923 | G218: 0.000972 | H218: 0.8349 | I218: 0.306066 | J218: 0.0066 | K218: 0.025228 | L218: 1.153 | M218: 1.0823 | N218: 1.2478 | O218: FIX
A219: 3466867 | B219: 218 | C219: 10309 | D219: 3664 | E219: 777 | F219: 4.6296 | G219: 0.000959 | H219: 0.8358 | I219: 0.355418 | J219: 0.2121 | K219: 0.005958 | L219: 0.5099 | M219: 1.3761 | N219: 0.7017 | O219: PROTECT
A220: 1415896 | B220: 219 | C220: 11965 | D220: 4641 | E220: 174 | F220: 4.6231 | G220: 0.000957 | H220: 0.8368 | I220: 0.387881 | J220: 0.0375 | K220: 0.02657 | L220: 0.6043 | M220: 1.54 | N220: 0.9306 | O220: FIX
A221: 21096019 | B221: 220 | C221: 22209 | D221: 8216 | E221: 68 | F221: 4.5763 | G221: 0.000948 | H221: 0.8377 | I221: 0.36994 | J221: 0.0083 | K221: 0.067299 | L221: 0.7609 | M221: 0.9696 | N221: 0.7377 | O221: FIX
A222: 28864843 | B222: 221 | C222: 6352 | D222: 2477 | E222: 306 | F222: 4.5033 | G222: 0.000932 | H222: 0.8387 | I222: 0.389956 | J222: 0.1235 | K222: 0.014717 | L222: 1.0702 | M222: 0.9621 | N222: 1.0296 | O222: PROTECT
A223: 9042365 | B223: 222 | C223: 9071 | D223: 3283 | E223: 148 | F223: 4.4928 | G223: 0.00093 | H223: 0.8396 | I223: 0.361923 | J223: 0.0451 | K223: 0.030357 | L223: 1.5031 | M223: 0.7776 | N223: 1.1688 | O223: FIX
A224: 22419532 | B224: 223 | C224: 39020 | D224: 11980 | E224: 77 | F224: 4.4752 | G224: 0.000927 | H224: 0.8405 | I224: 0.307022 | J224: 0.0064 | K224: 0.05812 | L224: 1.3793 | M224: 0.6535 | N224: 0.9013 | O224: FIX
A225: 27091104 | B225: 224 | C225: 15325 | D225: 4781 | E225: 351 | F225: 4.4599 | G225: 0.000923 | H225: 0.8415 | I225: 0.311974 | J225: 0.0734 | K225: 0.012706 | L225: 0.8225 | M225: 1.1452 | N225: 0.9419 | O225: PROTECT
A226: 26389108 | B226: 225 | C226: 13571 | D226: 2263 | E226: 66 | F226: 4.4479 | G226: 0.000921 | H226: 0.8424 | I226: 0.166753 | J226: 0.0292 | K226: 0.067392 | L226: 1.8722 | M226: 0.7399 | N226: 1.3853 | O226: FIX
...

Sheet FloorData
A1: exchange | B1: min_floor_fen_cpm | C1: impressions | D1: at_risk_imps | E1: can_sell_at_x | F1: share_at_risk | G1: revenue_now_cny | H1: revenue_lower_cny | I1: revenue_upper_cny | J1: revenue_r50_cny | K1: upper_change | L1: breakeven_retention
A2: All | B2: 0 | C2: 4724634 | D2: 0 | E2: 0 | F2: 0 | G2: 4253.82 | H2: 4253.82 | I2: 4253.82 | J2: 4253.82 | K2: 0
A3: All | B3: 10 | C3: 4724634 | D3: 343546 | E3: 343546 | F3: 0.0727 | G3: 4253.82 | H3: 4235.39 | I3: 4269.74 | J3: 4252.56 | K3: 0.0037 | L3: 0.5367
A4: All | B4: 20 | C4: 4724634 | D4: 651540 | E4: 651540 | F4: 0.1379 | G4: 4253.82 | H4: 4191.81 | I4: 4322.12 | J4: 4256.96 | K4: 0.0161 | L4: 0.4759
A5: All | B5: 30 | C5: 4724634 | D5: 1164522 | E5: 1164522 | F5: 0.2465 | G5: 4253.82 | H5: 4076.85 | I5: 4426.21 | J5: 4251.53 | K5: 0.0405 | L5: 0.5066
A6: All | B6: 40 | C6: 4724634 | D6: 1628770 | E6: 1628770 | F6: 0.3447 | G6: 4253.82 | H6: 3924.18 | I6: 4575.69 | J6: 4249.93 | K6: 0.0757 | L6: 0.506
A7: All | B7: 50 | C7: 4724634 | D7: 1855204 | E7: 1855204 | F7: 0.3927 | G7: 4253.82 | H7: 3824.49 | I7: 4752.09 | J7: 4288.29 | K7: 0.1171 | L7: 0.4628
A8: All | B8: 60 | C8: 4724634 | D8: 2189630 | E8: 2189630 | F8: 0.4634 | G8: 4253.82 | H8: 3648.23 | I8: 4962.01 | J8: 4305.12 | K8: 0.1665 | L8: 0.461
A9: All | B9: 70 | C9: 4724634 | D9: 2385068 | E9: 2385068 | F9: 0.5048 | G9: 4253.82 | H9: 3522.82 | I9: 5192.36 | J9: 4357.59 | K9: 0.2206 | L9: 0.4378
A10: All | B10: 80 | C10: 4724634 | D10: 2677835 | E10: 2677835 | F10: 0.5668 | G10: 4253.82 | H10: 3311.16 | I10: 5453.43 | J10: 4382.3 | K10: 0.282 | L10: 0.44
A11: All | B11: 90 | C11: 4724634 | D11: 2838593 | E11: 2838593 | F11: 0.6008 | G11: 4253.82 | H11: 3176.3 | I11: 5731.04 | J11: 4453.67 | K11: 0.3473 | L11: 0.4218
A12: All | B12: 100 | C12: 4724634 | D12: 2954446 | E12: 2954446 | F12: 0.6253 | G12: 4253.82 | H12: 3067.41 | I12: 6021.85 | J12: 4544.63 | K12: 0.4156 | L12: 0.4016
A13: All | B13: 110 | C13: 4724634 | D13: 3182697 | E13: 3182697 | F13: 0.6736 | G13: 4253.82 | H13: 2833.33 | I13: 6334.29 | J13: 4583.81 | K13: 0.4891 | L13: 0.4057
A14: All | B14: 120 | C14: 4724634 | D14: 3276995 | E14: 3276995 | F14: 0.6936 | G14: 4253.82 | H14: 2725.83 | I14: 6658.22 | J14: 4692.02 | K14: 0.5652 | L14: 0.3886
... A17: All | B17: 150 | C17: 4724634 | D17: 3600236 | E17: 3600236 | F17: 0.762 | G17: 4253.82 | H17: 2287.58 | I17: 7687.93 | J17: 4987.75 | K17: 0.8073 | L17: 0.3641
A18: Exchange 1 | B18: 0 | C18: 1167364 | D18: 0 | E18: 0 | F18: 0 | G18: 1193.8 | H18: 1193.8 | I18: 1193.8 | J18: 1193.8 | K18: 0
A19: Exchange 1 | B19: 10 | C19: 1167364 | D19: 44159 | E19: 44159 | F19: 0.0378 | G19: 1193.8 | H19: 1191.94 | I19: 1196.36 | J19: 1194.15 | K19: 0.0021 | L19: 0.4197
A20: Exchange 1 | B20: 20 | C20: 1167364 | D20: 127808 | E20: 127808 | F20: 0.1095 | G20: 1193.8 | H20: 1179.58 | I20: 1205.15 | J20: 1192.36 | K20: 0.0095 | L20: 0.5561
A21: Exchange 1 | B21: 30 | C21: 1167364 | D21: 222257 | E21: 222257 | F21: 0.1904 | G21: 1193.8 | H21: 1156.29 | I21: 1222.97 | J21: 1189.63 | K21: 0.0244 | L21: 0.5625
A22: Exchange 1 | B22: 40 | C22: 1167364 | D22: 320015 | E22: 320015 | F22: 0.2741 | G22: 1193.8 | H22: 1122.89 | I22: 1250.9 | J22: 1186.9 | K22: 0.0478 | L22: 0.5539
A23: Exchange 1 | B23: 50 | C23: 1167364 | D23: 388414 | E23: 388414 | F23: 0.3327 | G23: 1193.8 | H23: 1092.51 | I23: 1286.71 | J23: 1189.61 | K23: 0.0778 | L23: 0.5216
A24: Exchange 1 | B24: 60 | C24: 1167364 | D24: 477355 | E24: 477355 | F24: 0.4089 | G24: 1193.8 | H24: 1045.28 | I24: 1331.7 | J24: 1188.49 | K24: 0.1155 | L24: 0.5185
A25: Exchange 1 | B25: 70 | C25: 1167364 | D25: 534109 | E25: 534109 | F25: 0.4575 | G25: 1193.8 | H25: 1009.02 | I25: 1382.89 | J25: 1195.96 | K25: 0.1584 | L25: 0.4942
A26: Exchange 1 | B26: 80 | C26: 1167364 | D26: 580718 | E26: 580718 | F26: 0.4975 | G26: 1193.8 | H26: 974.69 | I26: 1439.27 | J26: 1206.98 | K26: 0.2056 | L26: 0.4716
A27: Exchange 1 | B27: 90 | C27: 1167364 | D27: 623698 | E27: 623698 | F27: 0.5343 | G27: 1193.8 | H27: 938.78 | I27: 1500.1 | J27: 1219.44 | K27: 0.2566 | L27: 0.4543
A28: Exchange 1 | B28: 100 | C28: 1167364 | D28: 652020 | E28: 652020 | F28: 0.5585 | G28: 1193.8 | H28: 912.24 | I28: 1564.26 | J28: 1238.25 | K28: 0.3103 | L28: 0.4318
A29: Exchange 1 | B29: 110 | C29: 1167364 | D29: 742488 | E29: 742488 | F29: 0.636 | G29: 1193.8 | H29: 819.89 | I29: 1636.63 | J29: 1228.26 | K29: 0.3709 | L29: 0.4578
A30: Exchange 1 | B30: 120 | C30: 1167364 | D30: 770608 | E30: 770608 | F30: 0.6601 | G30: 1193.8 | H30: 787.95 | I30: 1712.68 | J30: 1250.32 | K30: 0.4347 | L30: 0.4389
... A33: Exchange 1 | B33: 150 | C33: 1167364 | D33: 846711 | E33: 846711 | F33: 0.7253 | G33: 1193.8 | H33: 687.06 | I33: 1957.13 | J33: 1322.1 | K33: 0.6394 | L33: 0.399
A34: Exchange 2 | B34: 0 | C34: 1301471 | D34: 0 | E34: 0 | F34: 0 | G34: 1126.37 | H34: 1126.37 | I34: 1126.37 | J34: 1126.37 | K34: 0
A35: Exchange 2 | B35: 10 | C35: 1301471 | D35: 167502 | E35: 167502 | F35: 0.1287 | G35: 1126.37 | H35: 1116.72 | I35: 1133.47 | J35: 1125.09 | K35: 0.0063 | L35: 0.5766
A36: Exchange 2 | B36: 20 | C36: 1301471 | D36: 285058 | E36: 285058 | F36: 0.219 | G36: 1126.37 | H36: 1100.51 | I36: 1157.52 | J36: 1129.02 | K36: 0.0277 | L36: 0.4537
A37: Exchange 2 | B37: 30 | C37: 1301471 | D37: 372654 | E37: 372654 | F37: 0.2863 | G37: 1126.37 | H37: 1079.52 | I37: 1191.31 | J37: 1135.41 | K37: 0.0577 | L37: 0.4191
A38: Exchange 2 | B38: 40 | C38: 1301471 | D38: 444430 | E38: 444430 | F38: 0.3415 | G38: 1126.37 | H38: 1055.3 | I38: 1233.07 | J38: 1144.19 | K38: 0.0947 | L38: 0.3998
A39: Exchange 2 | B39: 50 | C39: 1301471 | D39: 498548 | E39: 498548 | F39: 0.3831 | G39: 1126.37 | H39: 1031.28 | I39: 1280.56 | J39: 1155.92 | K39: 0.1369 | L39: 0.3815
A40: Exchange 2 | B40: 60 | C40: 1301471 | D40: 584783 | E40: 584783 | F40: 0.4493 | G40: 1126.37 | H40: 985.07 | I40: 1335.94 | J40: 1160.51 | K40: 0.1861 | L40: 0.4027
A41: Exchange 2 | B41: 70 | C41: 1301471 | D41: 661018 | E41: 661018 | F41: 0.5079 | G41: 1126.37 | H41: 936.13 | I41: 1398.84 | J41: 1167.49 | K41: 0.2419 | L41: 0.4112
A42: Exchange 2 | B42: 80 | C42: 1301471 | D42: 703162 | E42: 703162 | F42: 0.5403 | G42: 1126.37 | H42: 904.86 | I42: 1467.39 | J42: 1186.13 | K42: 0.3028 | L42: 0.3938
A43: Exchange 2 | B43: 90 | C43: 1301471 | D43: 753472 | E43: 753472 | F43: 0.5789 | G43: 1126.37 | H43: 862.25 | I43: 1540.37 | J43: 1201.31 | K43: 0.3675 | L43: 0.3895
A44: Exchange 2 | B44: 100 | C44: 1301471 | D44: 798916 | E44: 798916 | F44: 0.6139 | G44: 1126.37 | H44: 819.61 | I44: 1618.53 | J44: 1219.07 | K44: 0.4369 | L44: 0.384
...
